2024-01-10 14:31:40.901 ERROR (MainThread) [homeassistant.components.homeassistant_alerts] Error requesting homeassistant_alerts data: Cannot connect to host alerts.home-assistant.io:443 ssl:default [Try again]
2024-01-10 14:31:44.167 ERROR (MainThread) [async_upnp_client.ssdp] Received error: [Errno 101] Network unreachable, transport: <_SelectorDatagramTransport fd=27 read=polling write=<idle, bufsize=0>>, socket: <asyncio.TransportSocket fd=27, family=2, type=2, proto=0, laddr=('0.0.0.0', 33509)>
2024-01-10 14:31:44.167 ERROR (MainThread) [async_upnp_client.ssdp] Received error: [Errno 101] Network unreachable, transport: <_SelectorDatagramTransport fd=27 read=polling write=<idle, bufsize=0>>, socket: <asyncio.TransportSocket fd=27, family=2, type=2, proto=0, laddr=('0.0.0.0', 33509)>
2024-01-10 14:31:44.167 ERROR (MainThread) [async_upnp_client.ssdp] Received error: [Errno 101] Network unreachable, transport: <_SelectorDatagramTransport fd=27 read=polling write=<idle, bufsize=0>>, socket: <asyncio.TransportSocket fd=27, family=2, type=2, proto=0, laddr=('0.0.0.0', 33509)>
2024-01-10 14:31:44.168 ERROR (MainThread) [async_upnp_client.ssdp] Received error: [Errno 101] Network unreachable, transport: <_SelectorDatagramTransport fd=29 read=polling write=<idle, bufsize=0>>, socket: <asyncio.TransportSocket fd=29, family=10, type=2, proto=0, laddr=('::', 42046, 0, 0)>
2024-01-10 14:31:44.169 ERROR (MainThread) [async_upnp_client.ssdp] Received error: [Errno 101] Network unreachable, transport: <_SelectorDatagramTransport fd=29 read=polling write=<idle, bufsize=0>>, socket: <asyncio.TransportSocket fd=29, family=10, type=2, proto=0, laddr=('::', 42046, 0, 0)>
2024-01-10 14:31:44.169 ERROR (MainThread) [async_upnp_client.ssdp] Received error: [Errno 101] Network unreachable, transport: <_SelectorDatagramTransport fd=29 read=polling write=<idle, bufsize=0>>, socket: <asyncio.TransportSocket fd=29, family=10, type=2, proto=0, laddr=('::', 42046, 0, 0)>
2024-01-10 14:31:44.170 WARNING (MainThread) [zeroconf] Error with socket 14 (('192.168.0.101', 5353))): [Errno 101] Network unreachable
Traceback (most recent call last):
  File "/usr/local/lib/python3.11/asyncio/selector_events.py", line 1190, in sendto
    self._sock.sendto(data, addr)
OSError: [Errno 101] Network unreachable
2024-01-10 14:31:44.172 WARNING (MainThread) [zeroconf] Error with socket 15 (('fe80::8baf:5b33:d024:8b82', 5353, 0, 3))): [Errno 101] Network unreachable
Traceback (most recent call last):
  File "/usr/local/lib/python3.11/asyncio/selector_events.py", line 1190, in sendto
    self._sock.sendto(data, addr)
OSError: [Errno 101] Network unreachable
